Workbook

Sheet website_sc_desc
A1: attribute | B1: vars | C1: n | D1: mean | E1: sd | F1: median | G1: trimmed | H1: mad | I1: min | J1: max | K1: range | L1: skew | M1: kurtosis | N1: se
A2: people_hs | B2: 1 | C2: 4478 | D2: 29240.189 | E2: 12896.286 | F2: 29652.5 | G2: 28731.357 | H2: 12523.522 | I2: 1632 | J2: 83258 | K2: 81626 | L2: 0.27091915 | M2: -0.47141867 | N2: 192.71815
A3: people_ls | B3: 2 | C3: 4325 | D3: 9856.4375 | E3: 10081.406 | F3: 7819 | G3: 8129.9873 | H3: 8753.2704 | I3: 0 | J3: 44590 | K3: 44590 | L3: 1.395766 | M3: 1.5100522 | N3: 153.29502
A4: people_score | B4: 3 | C4: 4478 | D4: 45.065984 | E4: 29.484336 | F4: 46.637483 | G4: 45.375975 | H4: 38.054693 | I4: 0 | J4: 93.46352 | K4: 93.46352 | L4: -0.13719862 | M4: -1.2703875 | N4: 0.44060489
A5: schools_hs | B5: 4 | C5: 4431 | D5: 8.1798691 | E5: 4.5332891 | F5: 8 | G5: 8.0668547 | H5: 5.9304 | I5: 1 | J5: 21 | K5: 20 | L5: 0.14255631 | M5: -0.97725961 | N5: 0.068102419
A6: schools_ls | B6: 5 | C6: 2777 | D6: 4.4602089 | E6: 2.6635179 | F6: 4 | G6: 4.3108412 | H6: 2.9652 | I6: 1 | J6: 14 | K6: 13 | L6: 0.39885548 | M6: -0.85271167 | N6: 0.050543775
A7: schools_score | B7: 6 | C7: 4431 | D7: 42.496191 | E7: 36.471861 | F7: 50 | G7: 41.943223 | H7: 49.42 | I7: 0 | J7: 100 | K7: 100 | L7: -0.07733148 | M7: -1.7309363 | N7: 0.54790726
A8: colleges_hs | B8: 7 | C8: 2397 | D8: 1.6020025 | E8: 0.56627181 | F8: 2 | G8: 1.5768629 | H8: 0 | I8: 1 | J8: 3 | K8: 2 | L8: 0.2630012 | M8: -0.80955441 | N8: 0.011566206
A9: colleges_ls | B9: 8 | C9: 997 | D9: 1.1454363 | E9: 0.35271713 | F9: 1 | G9: 1.057572 | H9: 0 | I9: 1 | J9: 2 | K9: 1 | L9: 2.008454 | M9: 2.0359325 | N9: 0.011170664
A10: colleges_score | B10: 9 | C10: 2397 | D10: 34.359616 | E10: 41.829719 | F10: 0 | G10: 30.463783 | H10: 0 | I10: 0 | J10: 100 | K10: 100 | L10: 0.50091508 | M10: -1.5470565 | N10: 0.85437972
A11: universities_hs | B11: 10 | C11: 1661 | D11: 1 | E11: 0 | F11: 1 | G11: 1 | H11: 0 | I11: 1 | J11: 1 | K11: 0 | L11: #NUM! | M11: #NUM! | N11: 0
A12: universities_ls | B12: 11 | C12: 663 | D12: 1 | E12: 0 | F12: 1 | G12: 1 | H12: 0 | I12: 1 | J12: 1 | K12: 0 | L12: #NUM! | M12: #NUM! | N12: 0
A13: universities_score | B13: 12 | C13: 1661 | D13: 39.915713 | E13: 48.987263 | F13: 0 | G13: 37.396539 | H13: 0 | I13: 0 | J13: 100 | K13: 100 | L13: 0.41146268 | M13: -1.8318002 | N13: 1.2019831
A14: doctors_hs | B14: 13 | C14: 3606 | D14: 3.9614531 | E14: 2.7904952 | F14: 3 | G14: 3.6514207 | H14: 2.9652 | I14: 1 | J14: 12 | K14: 11 | L14: 0.64895791 | M14: -0.73352138 | N14: 0.046469544
A15: doctors_ls | B15: 14 | C15: 1676 | D15: 2.4701671 | E15: 1.8610715 | F15: 2 | G15: 2.1304024 | H15: 1.4826 | I15: 1 | J15: 7 | K15: 6 | L15: 1.2587414 | M15: 0.41333163 | N15: 0.045459646
A16: doctors_score | B16: 15 | C16: 3606 | D16: 31.340227 | E16: 36.613884 | F16: 0 | G16: 26.961835 | H16: 0 | I16: 0 | J16: 100 | K16: 100 | L16: 0.58157305 | M16: -1.2281585 | N16: 0.60972351
A17: dentists_hs | B17: 16 | C17: 3272 | D17: 4.2182152 | E17: 3.3359806 | F17: 3 | G17: 3.6470588 | H17: 2.9652 | I17: 1 | J17: 15 | K17: 14 | L17: 1.2837092 | M17: 0.81137157 | N17: 0.058319912
A18: dentists_ls | B18: 17 | C18: 1758 | D18: 2.0819113 | E18: 1.4967627 | F18: 2 | G18: 1.7698864 | H18: 1.4826 | I18: 1 | J18: 10 | K18: 9 | L18: 2.1614848 | M18: 5.6700827 | N18: 0.03569797
A19: dentists_score | B19: 18 | C19: 3272 | D19: 32.984345 | E19: 34.159753 | F19: 40 | G19: 29.220028 | H19: 59.304 | I19: 0 | J19: 100 | K19: 100 | L19: 0.45542478 | M19: -1.1224317 | N19: 0.59718387
A20: hospitals_hs | B20: 19 | C20: 1784 | D20: 2.2976457 | E20: 1.6046326 | F20: 1 | G20: 2.122549 | H20: 0 | I20: 1 | J20: 5 | K20: 4 | L20: 0.81191044 | M20: -0.98356989 | N20: 0.037990778
A21: hospitals_ls | B21: 20 | C21: 761 | D21: 1.9894875 | E21: 0.88251726 | F21: 2 | G21: 1.9047619 | H21: 1.4826 | I21: 1 | J21: 5 | K21: 4 | L21: 1.0527758 | M21: 1.7112317 | N21: 0.031991226
A22: hospitals_score | B22: 21 | C22: 1784 | D22: 37.436939 | E22: 44.105741 | F22: 0 | G22: 34.304972 | H22: 0 | I22: 0 | J22: 100 | K22: 100 | L22: 0.38816071 | M22: -1.7382684 | N22: 1.0442337
A23: pharmacies_hs | B23: 22 | C23: 3987 | D23: 3.9044394 | E23: 2.520194 | F23: 4 | G23: 3.5377625 | H23: 1.4826 | I23: 1 | J23: 13 | K23: 12 | L23: 1.1264763 | M23: 0.73574726 | N23: 0.039912676
A24: pharmacies_ls | B24: 23 | C24: 2277 | D24: 2.2125604 | E24: 1.795464 | F24: 1 | G24: 1.8080088 | H24: 0 | I24: 1 | J24: 8 | K24: 7 | L24: 1.6030707 | M24: 1.4722531 | N24: 0.037626618
... A47: recreation_score | B47: 46 | C47: 4478 | D47: 36.021768 | E47: 18.713108 | F47: 42.6875 | G47: 37.727973 | H47: 15.103988 | I47: 0 | J47: 63.235294 | K47: 63.235294 | L47: -0.81820917 | M47: -0.53195426 | N47: 0.27964296

Sheet pybna_sc_desc
A1: attribute | B1: vars | C1: n | D1: mean | E1: sd | F1: median | G1: trimmed | H1: mad | I1: min | J1: max | K1: range | L1: skew | M1: kurtosis | N1: se
A2: people_hs | B2: 1 | C2: 4336 | D2: 20356.142 | E2: 11711.245 | F2: 18940.5 | G2: 19288.738 | H2: 9900.0615 | I2: 0 | J2: 54527 | K2: 54527 | L2: 0.75295651 | M2: 0.21281991 | N2: 177.85187
A3: people_ls | B3: 2 | C3: 4336 | D3: 7111.2442 | E3: 7299.4893 | F3: 5486 | G3: 5873.9738 | H3: 6157.9791 | I3: 0 | J3: 38182 | K3: 38182 | L3: 1.6140805 | M3: 2.9210162 | N3: 110.8531
A4: people_score | B4: 3 | C4: 4334 | D4: 49.530675 | E4: 29.538294 | F4: 53.670559 | G4: 50.761176 | H4: 37.390616 | I4: 0 | J4: 100 | K4: 100 | L4: -0.33688024 | M4: -1.1317388 | N4: 0.44868439
A5: schools_hs | B5: 4 | C5: 4043 | D5: 6.2807321 | E5: 3.6732706 | F5: 6 | G5: 6.150541 | H5: 4.4478 | I5: 1 | J5: 16 | K5: 15 | L5: 0.22762092 | M5: -1.0139923 | N5: 0.057769824
A6: schools_ls | B6: 5 | C6: 2742 | D6: 3.3694384 | E6: 2.2566743 | F6: 3 | G6: 3.0834093 | H6: 2.9652 | I6: 1 | J6: 13 | K6: 12 | L6: 0.88563586 | M6: 0.0072242413 | N6: 0.043095821
A7: schools_score | B7: 6 | C7: 4043 | D7: 43.503096 | E7: 35.249875 | F7: 50 | G7: 42.582349 | H7: 46.33125 | I7: 0 | J7: 100 | K7: 100 | L7: -0.030184323 | M7: -1.5125881 | N7: 0.55437764
A8: colleges_hs | B8: 7 | C8: 1882 | D8: 1.466525 | E8: 0.51783249 | F8: 1 | G8: 1.4462151 | H8: 0 | I8: 1 | J8: 3 | K8: 2 | L8: 0.34046787 | M8: -1.4027664 | N8: 0.011936568
A9: colleges_ls | B9: 8 | C9: 586 | D9: 1.1365188 | E9: 0.34363193 | F9: 1 | G9: 1.0468085 | H9: 0 | I9: 1 | J9: 2 | K9: 1 | L9: 2.1119164 | M9: 2.4644051 | N9: 0.014195304
A10: colleges_score | B10: 9 | C10: 1882 | D10: 26.370882 | E10: 40.110912 | F10: 0 | G10: 20.471448 | H10: 0 | I10: 0 | J10: 100 | K10: 100 | L10: 0.95200424 | M10: -0.91750468 | N10: 0.92459752
A11: universities_hs | B11: 10 | C11: 1194 | D11: 1 | E11: 0 | F11: 1 | G11: 1 | H11: 0 | I11: 1 | J11: 1 | K11: 0 | L11: #NUM! | M11: #NUM! | N11: 0
A12: universities_ls | B12: 11 | C12: 529 | D12: 1 | E12: 0 | F12: 1 | G12: 1 | H12: 0 | I12: 1 | J12: 1 | K12: 0 | L12: #NUM! | M12: #NUM! | N12: 0
A13: universities_score | B13: 12 | C13: 1194 | D13: 44.304858 | E13: 49.695409 | F13: 0 | G13: 42.887029 | H13: 0 | I13: 0 | J13: 100 | K13: 100 | L13: 0.22900999 | M13: -1.9491848 | N13: 1.4381829
A14: doctors_hs | B14: 13 | C14: 3094 | D14: 3.2252747 | E14: 2.3791844 | F14: 2 | G14: 2.8824717 | H14: 1.4826 | I14: 1 | J14: 10 | K14: 9 | L14: 0.97242791 | M14: -0.14774439 | N14: 0.042772826
A15: doctors_ls | B15: 14 | C15: 1391 | D15: 2.1063983 | E15: 1.4672082 | F15: 2 | G15: 1.8185085 | H15: 1.4826 | I15: 1 | J15: 7 | K15: 6 | L15: 1.3686871 | M15: 0.95302025 | N15: 0.039339442
A16: doctors_score | B16: 15 | C16: 3094 | D16: 30.74312 | E16: 37.259051 | F16: 0 | G16: 25.936678 | H16: 0 | I16: 0 | J16: 100 | K16: 100 | L16: 0.67092243 | M16: -1.1057771 | N16: 0.66984086
A17: dentists_hs | B17: 16 | C17: 2896 | D17: 3.2634669 | E17: 2.5789084 | F17: 3 | G17: 2.7605695 | H17: 1.4826 | I17: 1 | J17: 13 | K17: 12 | L17: 1.6378379 | M17: 2.2941513 | N17: 0.047922188
A18: dentists_ls | B18: 17 | C18: 1460 | D18: 1.7684932 | E18: 1.2144184 | F18: 1 | G18: 1.4811644 | H18: 0 | I18: 1 | J18: 7 | K18: 6 | L18: 2.186131 | M18: 5.0865103 | N18: 0.031782781
A19: dentists_score | B19: 18 | C19: 2896 | D19: 31.774566 | E19: 35.665773 | F19: 40 | G19: 27.230001 | H19: 59.304 | I19: 0 | J19: 100 | K19: 100 | L19: 0.64090282 | M19: -0.9436891 | N19: 0.662754
A20: hospitals_hs | B20: 19 | C20: 0 | D20: #NUM! | G20: #NUM! | I20: #NUM! | J20: #NUM! | K20: #NUM!
A21: hospitals_ls | B21: 20 | C21: 0 | D21: #NUM! | G21: #NUM! | I21: #NUM! | J21: #NUM! | K21: #NUM!
A22: hospitals_score | B22: 21 | C22: 0 | D22: #NUM! | G22: #NUM! | I22: #NUM! | J22: #NUM! | K22: #NUM!
A23: pharmacies_hs | B23: 22 | C23: 3363 | D23: 3.1236991 | E23: 2.3096506 | F23: 2 | G23: 2.7090301 | H23: 1.4826 | I23: 1 | J23: 11 | K23: 10 | L23: 1.3361261 | M23: 1.0705707 | N23: 0.039827482
A24: pharmacies_ls | B24: 23 | C24: 1730 | D24: 1.9277457 | E24: 1.4417489 | F24: 1 | G24: 1.591763 | H24: 0 | I24: 1 | J24: 7 | K24: 6 | L24: 1.8436713 | M24: 2.7425628 | N24: 0.034663034
A25: pharmacies_score | B25: 24 | C25: 3363 | D25: 32.147254 | E25: 35.380444 | F25: 40 | G25: 27.729734 | H25: 59.304 | I25: 0 | J25: 100 | K25: 100 | L25: 0.59957938 | M25: -1.0039129 | N25: 0.61009833
A26: supermarkets_hs | B26: 25 | C26: 3928 | D26: 3.6387475 | E26: 2.2764381 | F26: 3 | G26: 3.355598 | H26: 2.9652 | I26: 1 | J26: 11 | K26: 10 | L26: 0.94369404 | M26: 0.50387989 | N26: 0.036322029
A27: supermarkets_ls | B27: 26 | C27: 2242 | D27: 1.9634255 | E27: 1.370467 | F27: 1 | G27: 1.6761427 | H27: 0 | I27: 1 | J27: 8 | K27: 7 | L27: 1.574448 | M27: 1.8552911 | N27: 0.028943482
A28: supermarkets_score | B28: 27 | C28: 3928 | D28: 43.007623 | E28: 39.132044 | F28: 60 | G28: 41.329938 | H28: 59.304 | I28: 0 | J28: 100 | K28: 100 | L28: -0.0093350436 | M28: -1.6718766 | N28: 0.62437685
A29: social_services_hs | B29: 28 | C29: 2937 | D29: 2.9550562 | E29: 1.6811654 | F29: 2 | G29: 2.7358571 | H29: 1.4826 | I29: 1 | J29: 8 | K29: 7 | L29: 1.0441364 | M29: 0.50569398 | N29: 0.031021192
A30: social_services_ls | B30: 29 | C30: 1787 | D30: 1.8164522 | E30: 1.0319087 | F30: 1 | G30: 1.6512928 | H30: 0 | I30: 1 | J30: 6 | K30: 5 | L30: 1.1724826 | M30: 0.75565952 | N30: 0.02441063
A31: social_services_score | B31: 30 | C31: 2937 | D31: 49.950289 | E31: 41.182782 | F31: 70 | G31: 49.937899 | H31: 44.478 | I31: 0 | J31: 100 | K31: 100 | L31: -0.27916333 | M31: -1.7067555 | N31: 0.75991272
A32: parks_hs | B32: 31 | C32: 4258 | D32: 19.883748 | E32: 10.018909 | F32: 19 | G32: 19.343603 | H32: 10.3782 | I32: 1 | J32: 64 | K32: 63 | L32: 0.66703156 | M32: 0.85872141 | N32: 0.15353861
A33: parks_ls | B33: 32 | C33: 3511 | D33: 8.5163771 | E33: 6.4232663 | F33: 7 | G33: 7.8031328 | H33: 5.9304 | I33: 1 | J33: 41 | K33: 40 | L33: 1.5922127 | M33: 4.3718861 | N33: 0.1084028
A34: parks_score | B34: 33 | C34: 4258 | D34: 60.626001 | E34: 32.300992 | F34: 76 | G34: 64.127684 | H34: 14.23296 | I34: 0 | J34: 100 | K34: 100 | L34: -0.99378038 | M34: -0.55878117 | N34: 0.49500893
A35: community_centers_hs | B35: 34 | C35: 0 | D35: #NUM! | G35: #NUM! | I35: #NUM! | J35: #NUM! | K35: #NUM!
A36: community_centers_ls | B36: 35 | C36: 0 | D36: #NUM! | G36: #NUM! | I36: #NUM! | J36: #NUM! | K36: #NUM!
A37: community_centers_score | B37: 36 | C37: 0 | D37: #NUM! | G37: #NUM! | I37: #NUM! | J37: #NUM! | K37: #NUM!
A38: retail_hs | B38: 37 | C38: 3718 | D38: 11.561323 | E38: 9.5637914 | F38: 9 | G38: 9.9969758 | H38: 7.413 | I38: 1 | J38: 51 | K38: 50 | L38: 1.4963805 | M38: 2.2034359 | N38: 0.15684671
A39: retail_ls | B39: 38 | C39: 2540 | D39: 4.896063 | E39: 3.9396071 | F39: 4 | G39: 4.3233268 | H39: 4.4478 | I39: 1 | J39: 29 | K39: 28 | L39: 1.4002301 | M39: 2.5887283 | N39: 0.07816927
A40: retail_score | B40: 39 | C40: 3718 | D40: 48.494143 | E40: 36.426484 | F40: 60 | G40: 48.605203 | H40: 34.594 | I40: 0 | J40: 100 | K40: 100 | L40: -0.29954068 | M40: -1.502103 | N40: 0.59739635
...

Sheet website_nulls
A1: attribute | B1: website_scores_nas | C1: website_scores_not_nas | D1: total | E1: na_percent | F1: not_na_percent
A2: blockid10 | B2: 0 | C2: 4489 | D2: 4489 | E2: 0 | F2: 100
A3: people_hs | B3: 11 | C3: 4478 | D3: 4489 | E3: 0.25 | F3: 99.75
A4: people_ls | B4: 164 | C4: 4325 | D4: 4489 | E4: 3.65 | F4: 96.35
A5: people_score | B5: 11 | C5: 4478 | D5: 4489 | E5: 0.25 | F5: 99.75
A6: schools_hs | B6: 58 | C6: 4431 | D6: 4489 | E6: 1.29 | F6: 98.71
A7: schools_ls | B7: 1712 | C7: 2777 | D7: 4489 | E7: 38.14 | F7: 61.86
A8: schools_score | B8: 58 | C8: 4431 | D8: 4489 | E8: 1.29 | F8: 98.71
A9: colleges_hs | B9: 2092 | C9: 2397 | D9: 4489 | E9: 46.6 | F9: 53.4
A10: colleges_ls | B10: 3492 | C10: 997 | D10: 4489 | E10: 77.79 | F10: 22.21
A11: colleges_score | B11: 2092 | C11: 2397 | D11: 4489 | E11: 46.6 | F11: 53.4
A12: universities_hs | B12: 2828 | C12: 1661 | D12: 4489 | E12: 63 | F12: 37
A13: universities_ls | B13: 3826 | C13: 663 | D13: 4489 | E13: 85.23 | F13: 14.77
... A49: geom | B49: 0 | C49: 4489 | D49: 4489 | E49: 0 | F49: 100

Sheet pybna_score_nulls
A1: attribute | B1: new_scores_nas | C1: new_scores_not_nas | D1: total | E1: na_percent | F1: not_na_percent
A2: blockid10 | B2: 0 | C2: 4489 | D2: 4489 | E2: 0 | F2: 100
A3: people_hs | B3: 153 | C3: 4336 | D3: 4489 | E3: 3.41 | F3: 96.59
A4: people_ls | B4: 153 | C4: 4336 | D4: 4489 | E4: 3.41 | F4: 96.59
A5: people_score | B5: 155 | C5: 4334 | D5: 4489 | E5: 3.45 | F5: 96.55
A6: schools_hs | B6: 446 | C6: 4043 | D6: 4489 | E6: 9.94 | F6: 90.06
A7: schools_ls | B7: 1747 | C7: 2742 | D7: 4489 | E7: 38.92 | F7: 61.08
A8: schools_score | B8: 446 | C8: 4043 | D8: 4489 | E8: 9.94 | F8: 90.06
A9: colleges_hs | B9: 2607 | C9: 1882 | D9: 4489 | E9: 58.08 | F9: 41.92
A10: colleges_ls | B10: 3903 | C10: 586 | D10: 4489 | E10: 86.95 | F10: 13.05
A11: colleges_score | B11: 2607 | C11: 1882 | D11: 4489 | E11: 58.08 | F11: 41.92
A12: universities_hs | B12: 3295 | C12: 1194 | D12: 4489 | E12: 73.4 | F12: 26.6
A13: universities_ls | B13: 3960 | C13: 529 | D13: 4489 | E13: 88.22 | F13: 11.78
... A49: geom | B49: 0 | C49: 4489 | D49: 4489 | E49: 0 | F49: 100

Sheet null_delta
A1: attribute | B1: website_score_null_percent | C1: pybna_score_null_percents | D1: difference
A2: blockid10 | B2: =VLOOKUP(A2, website_nulls!$A$1:$F$49, 5, FALSE) -> 0 | C2: =VLOOKUP(A2, pybna_score_nulls!$A$1:$E$49, 5, FALSE) -> 0 | D2: =C2-B2 -> 0
A3: people_hs | B3: =VLOOKUP(A3, website_nulls!$A$1:$F$49, 5, FALSE) -> 0.25 | C3: =VLOOKUP(A3, pybna_score_nulls!$A$1:$E$49, 5, FALSE) -> 3.41 | D3: =C3-B3 -> 3.16
A4: people_ls | B4: =VLOOKUP(A4, website_nulls!$A$1:$F$49, 5, FALSE) -> 3.65 | C4: =VLOOKUP(A4, pybna_score_nulls!$A$1:$E$49, 5, FALSE) -> 3.41 | D4: =C4-B4 -> -0.24
A5: people_score | B5: =VLOOKUP(A5, website_nulls!$A$1:$F$49, 5, FALSE) -> 0.25 | C5: =VLOOKUP(A5, pybna_score_nulls!$A$1:$E$49, 5, FALSE) -> 3.45 | D5: =C5-B5 -> 3.2
A6: schools_hs | B6: =VLOOKUP(A6, website_nulls!$A$1:$F$49, 5, FALSE) -> 1.29 | C6: =VLOOKUP(A6, pybna_score_nulls!$A$1:$E$49, 5, FALSE) -> 9.94 | D6: =C6-B6 -> 8.65
A7: schools_ls | B7: =VLOOKUP(A7, website_nulls!$A$1:$F$49, 5, FALSE) -> 38.14 | C7: =VLOOKUP(A7, pybna_score_nulls!$A$1:$E$49, 5, FALSE) -> 38.92 | D7: =C7-B7 -> 0.78
A8: schools_score | B8: =VLOOKUP(A8, website_nulls!$A$1:$F$49, 5, FALSE) -> 1.29 | C8: =VLOOKUP(A8, pybna_score_nulls!$A$1:$E$49, 5, FALSE) -> 9.94 | D8: =C8-B8 -> 8.65
A9: colleges_hs | B9: =VLOOKUP(A9, website_nulls!$A$1:$F$49, 5, FALSE) -> 46.6 | C9: =VLOOKUP(A9, pybna_score_nulls!$A$1:$E$49, 5, FALSE) -> 58.08 | D9: =C9-B9 -> 11.48
A10: colleges_ls | B10: =VLOOKUP(A10, website_nulls!$A$1:$F$49, 5, FALSE) -> 77.79 | C10: =VLOOKUP(A10, pybna_score_nulls!$A$1:$E$49, 5, FALSE) -> 86.95 | D10: =C10-B10 -> 9.16
A11: colleges_score | B11: =VLOOKUP(A11, website_nulls!$A$1:$F$49, 5, FALSE) -> 46.6 | C11: =VLOOKUP(A11, pybna_score_nulls!$A$1:$E$49, 5, FALSE) -> 58.08 | D11: =C11-B11 -> 11.48
A12: universities_hs | B12: =VLOOKUP(A12, website_nulls!$A$1:$F$49, 5, FALSE) -> 63 | C12: =VLOOKUP(A12, pybna_score_nulls!$A$1:$E$49, 5, FALSE) -> 73.4 | D12: =C12-B12 -> 10.4
A13: universities_ls | B13: =VLOOKUP(A13, website_nulls!$A$1:$F$49, 5, FALSE) -> 85.23 | C13: =VLOOKUP(A13, pybna_score_nulls!$A$1:$E$49, 5, FALSE) -> 88.22 | D13: =C13-B13 -> 2.99
... A49: geom | B49: =VLOOKUP(A49, website_nulls!$A$1:$F$49, 5, FALSE) -> 0 | C49: =VLOOKUP(A49, pybna_score_nulls!$A$1:$E$49, 5, FALSE) -> 0 | D49: =C49-B49 -> 0

Sheet mean_score_comparison
A1: attribute | B1: mean_web_sc | C1: mean_pybna_sc | D1: difference | E1: direction
A2: colleges_score | B2: 34.359616 | C2: 26.370882 | D2: 7.99 | E2: lower
A3: community_centers_score | B3: 38.500302 | C3: #NUM! | D3: #NUM!
A4: core_services_score | B4: 37.335439 | C4: 36.705272 | D4: 0.63 | E4: lower
A5: dentists_score | B5: 32.984345 | C5: 31.774566 | D5: 1.21 | E5: lower
A6: doctors_score | B6: 31.340227 | C6: 30.74312 | D6: 0.6 | E6: lower
A7: hospitals_score | B7: 37.436939 | C7: #NUM! | D7: #NUM!
A8: opportunity_score | B8: 24.575887 | C8: 25.914281 | D8: 1.34 | E8: higher
A9: overall_score | B9: 41.667677 | C9: 43.937458 | D9: 2.27 | E9: higher
A10: parks_score | B10: 63.484242 | C10: 60.626001 | D10: 2.86 | E10: lower
A11: people_score | B11: 45.065984 | C11: 49.530675 | D11: 4.46 | E11: higher
A12: pharmacies_score | B12: 34.208616 | C12: 32.147254 | D12: 2.06 | E12: lower
A13: recreation_score | B13: 36.021768 | C13: 39.406901 | D13: 3.39 | E13: higher
A14: retail_score | B14: 46.435881 | C14: 48.494143 | D14: 2.06 | E14: higher
A15: schools_score | B15: 42.496191 | C15: 43.503096 | D15: 1.01 | E15: higher
A16: social_services_score | B16: 50.679991 | C16: 49.950289 | D16: 0.73 | E16: lower
A17: supermarkets_score | B17: 46.04018 | C17: 43.007623 | D17: 3.03 | E17: lower
A18: transit_score | B18: 22.451362 | C18: 17.30038 | D18: 5.15 | E18: lower
A19: universities_score | B19: 39.915713 | C19: 44.304858 | D19: 4.39 | E19: higher

Sheet min_mean_median_max_scores
A1: attribute | B1: min_webs_sc | C1: median_webs_sc | D1: mean_webs_sc | E1: max_webs_sc | F1: min_pybna_sc | G1: median_pybna_sc | H1: mean_pybna_sc | I1: max_pybna_sc
A2: colleges_score | B2: 0 | C2: 0 | D2: 34.359616 | E2: 100 | F2: 0 | G2: 0 | H2: 26.370882 | I2: 100
A3: community_centers_score | B3: 0 | C3: 40 | D3: 38.500302 | E3: 100 | F3: #NUM! | H3: #NUM! | I3: #NUM!
A4: core_services_score | B4: 0 | C4: 40 | D4: 37.335439 | E4: 100 | F4: 0 | G4: 37.5 | H4: 36.705272 | I4: 100
A5: dentists_score | B5: 0 | C5: 40 | D5: 32.984345 | E5: 100 | F5: 0 | G5: 40 | H5: 31.774566 | I5: 100
A6: doctors_score | B6: 0 | C6: 0 | D6: 31.340227 | E6: 100 | F6: 0 | G6: 0 | H6: 30.74312 | I6: 100
A7: hospitals_score | B7: 0 | C7: 0 | D7: 37.436939 | E7: 100 | F7: #NUM! | H7: #NUM! | I7: #NUM!
A8: opportunity_score | B8: 0 | C8: 25.277778 | D8: 24.575887 | E8: 65 | F8: 0 | G8: 25.277778 | H8: 25.914281 | I8: 65
A9: overall_score | B9: 0 | C9: 46.239678 | D9: 41.667677 | E9: 92.293701 | F9: 0 | G9: 48.020907 | H9: 43.937458 | I9: 100
A10: parks_score | B10: 0 | C10: 76.521739 | D10: 63.484242 | E10: 95.588235 | F10: 0 | G10: 76 | H10: 60.626001 | I10: 100
A11: people_score | B11: 0 | C11: 46.637483 | D11: 45.065984 | E11: 93.46352 | F11: 0 | G11: 53.670559 | H11: 49.530675 | I11: 100
A12: pharmacies_score | B12: 0 | C12: 40 | D12: 34.208616 | E12: 100 | F12: 0 | G12: 40 | H12: 32.147254 | I12: 100
A13: recreation_score | B13: 0 | C13: 42.6875 | D13: 36.021768 | E13: 63.235294 | F13: 0 | G13: 49.4 | H13: 39.406901 | I13: 65
A14: retail_score | B14: 0 | C14: 60 | D14: 46.435881 | E14: 100 | F14: 0 | G14: 60 | H14: 48.494143 | I14: 100
A15: schools_score | B15: 0 | C15: 50 | D15: 42.496191 | E15: 100 | F15: 0 | G15: 50 | H15: 43.503096 | I15: 100
A16: social_services_score | B16: 0 | C16: 70 | D16: 50.679991 | E16: 100 | F16: 0 | G16: 70 | H16: 49.950289 | I16: 100
A17: supermarkets_score | B17: 0 | C17: 60 | D17: 46.04018 | E17: 100 | F17: 0 | G17: 60 | H17: 43.007623 | I17: 100
A18: transit_score | B18: 0 | C18: 0 | D18: 22.451362 | E18: 100 | F18: 0 | G18: 0 | H18: 17.30038 | I18: 100
A19: universities_score | B19: 0 | C19: 0 | D19: 39.915713 | E19: 100 | F19: 0 | G19: 0 | H19: 44.304858 | I19: 100

Sheet website_raw
A1: blockid10 | B1: people_hs | C1: people_ls | D1: people_score | E1: schools_hs | F1: schools_ls | G1: schools_score | H1: colleges_hs | I1: colleges_ls | J1: colleges_score | K1: universities_hs | L1: universities_ls | M1: universities_score | N1: doctors_hs | O1: doctors_ls | P1: doctors_score | Q1: dentists_hs | R1: dentists_ls | S1: dentists_score | T1: hospitals_hs | U1: hospitals_ls | V1: hospitals_score | W1: pharmacies_hs | X1: pharmacies_ls | Y1: pharmacies_score | Z1: supermarkets_hs | AA1: supermarkets_ls | AB1: supermarkets_score | AC1: social_services_hs | AD1: social_services_ls | AE1: social_services_score | AF1: parks_hs | AG1: parks_ls | AH1: parks_score | AI1: community_centers_hs | AJ1: community_centers_ls | AK1: community_centers_score | AL1: retail_hs | AM1: retail_ls | AN1: retail_score | AO1: transit_hs | AP1: transit_ls | AQ1: transit_score | AR1: overall_score | AS1: opportunity_score | AT1: core_services_score | AU1: recreation_score
A2: 550250114013123 | B2: 7336 | C2: 4 | D2: 0.18175209 | E2: 2 | G2: 0 | AF2: 36 | AG2: 1 | AH2: 30 | AL2: 1 | AN2: 0 | AR2: 6.9650197 | AS2: 0 | AU2: 19.5
A3: 550250114023092 | B3: 4467 | C3: 14 | D3: 1.0446982 | T3: 1 | V3: 0 | AF3: 7 | AH3: 0 | AL3: 1 | AN3: 0 | AR3: 0.24108419 | AT3: 0 | AU3: 0
A4: 550250114013083 | B4: 6465 | D4: 0 | E4: 1 | G4: 0 | AF4: 30 | AH4: 0 | AL4: 1 | AN4: 0 | AR4: 0 | AS4: 0 | AU4: 0
A5: 550250114013085 | B5: 6546 | C5: 0 | D5: 0 | E5: 1 | G5: 0 | AF5: 27 | AH5: 0 | AL5: 1 | AN5: 0 | AR5: 0 | AS5: 0 | AU5: 0
A6: 550250109031042 | B6: 5538 | C6: 1630 | D6: 52.577344 | E6: 2 | F6: 1 | G6: 30 | AF6: 26 | AG6: 7 | AH6: 75.217391 | AR6: 50.338421 | AS6: 19.5 | AU6: 48.891304
A7: 550250109031043 | B7: 7804 | C7: 1875 | D7: 45.368187 | E7: 2 | F7: 1 | G7: 30 | Z7: 1 | AB7: 0 | AF7: 34 | AG7: 7 | AH7: 73.870968 | AR7: 34.122676 | AS7: 19.5 | AT7: 0 | AU7: 48.016129
A8: 550250109031045 | B8: 7853 | C8: 249 | D8: 10.301346 | E8: 2 | G8: 0 | Z8: 1 | AB8: 0 | AF8: 33 | AG8: 1 | AH8: 30 | AR8: 8.6360027 | AS8: 0 | AT8: 0 | AU8: 19.5
A9: 550250109031047 | B9: 5960 | C9: 1788 | D9: 53.333333 | E9: 2 | F9: 1 | G9: 30 | AF9: 28 | AG9: 7 | AH9: 74.8 | AR9: 50.44 | AS9: 19.5 | AU9: 48.62
A10: 550250109031048 | B10: 4813 | C10: 338 | D10: 17.098789 | E10: 2 | G10: 0 | AF10: 20 | AG10: 2 | AH10: 50 | AR10: 20.129637 | AS10: 0 | AU10: 32.5
A11: 550250109031049 | B11: 5758 | C11: 166 | D11: 9.6098182 | E11: 2 | G11: 0 | AF11: 28 | AG11: 2 | AH11: 50 | AR11: 17.882945 | AS11: 0 | AU11: 32.5
A12: 550250109031051 | B12: 7082 | C12: 2290 | D12: 56.447331 | E12: 2 | F12: 1 | G12: 30 | AF12: 29 | AG12: 7 | AH12: 74.615385 | AR12: 51.318815 | AS12: 19.5 | AU12: 48.5
A13: 550250109031052 | B13: 6524 | C13: 2174 | D13: 57.764153 | E13: 2 | F13: 1 | G13: 30 | AF13: 29 | AG13: 7 | AH13: 74.615385 | AR13: 51.713861 | AS13: 19.5 | AU13: 48.5
A14: 550250109031053 | B14: 5477 | C14: 1788 | D14: 56.860812 | E14: 2 | F14: 1 | G14: 30 | AF14: 26 | AG14: 7 | AH14: 75.217391 | AR14: 51.623461 | AS14: 19.5 | AU14: 48.891304
A15: 550250109031054 | B15: 6992 | C15: 2202 | D15: 55.32418 | E15: 2 | F15: 1 | G15: 30 | AF15: 29 | AG15: 7 | AH15: 74.615385 | AR15: 50.981869 | AS15: 19.5 | AU15: 48.5
A16: 550250109031055 | B16: 6692 | C16: 2254 | D16: 58.242678 | E16: 2 | F16: 1 | G16: 30 | AF16: 29 | AG16: 7 | AH16: 74.615385 | AR16: 51.857419 | AS16: 19.5 | AU16: 48.5
A17: 550250109031056 | B17: 4651 | C17: 166 | D17: 11.004338 | E17: 2 | G17: 0 | AF17: 17 | AG17: 2 | AH17: 50 | AR17: 18.301301 | AS17: 0 | AU17: 32.5
A18: 550250114013109 | B18: 6928 | C18: 2 | D18: 0.096227868 | E18: 2 | G18: 0 | AF18: 37 | AG18: 1 | AH18: 30 | AL18: 2 | AN18: 0 | AR18: 6.9452834 | AS18: 0 | AU18: 19.5
A19: 550250114013110 | B19: 8093 | C19: 48 | D19: 1.9770172 | E19: 2 | G19: 0 | AF19: 40 | AH19: 0 | AL19: 2 | AN19: 0 | AR19: 0.45623473 | AS19: 0 | AU19: 0
A20: 550250114013111 | B20: 6984 | C20: 48 | D20: 2.2909507 | E20: 2 | G20: 0 | AF20: 40 | AH20: 0 | AL20: 2 | AN20: 0 | AR20: 0.52868094 | AS20: 0 | AU20: 0
A21: 550250114013112 | B21: 6625 | D21: 0 | E21: 2 | G21: 0 | AF21: 37 | AH21: 0 | AL21: 2 | AN21: 0 | AR21: 0 | AS21: 0 | AU21: 0
A22: 550250114013113 | B22: 6764 | C22: 48 | D22: 2.3654642 | E22: 2 | G22: 0 | AF22: 39 | AH22: 0 | AL22: 1 | AN22: 0 | AR22: 0.54587636 | AS22: 0 | AU22: 0
A23: 550250114013120 | B23: 2818 | D23: 0 | E23: 1 | G23: 0 | AF23: 23 | AH23: 0 | AL23: 1 | AN23: 0 | AR23: 0 | AS23: 0 | AU23: 0
A24: 550250114013121 | B24: 7008 | C24: 2 | D24: 0.095129376 | E24: 2 | G24: 0 | AF24: 37 | AG24: 1 | AH24: 30 | AL24: 1 | AN24: 0 | AR24: 6.9450299 | AS24: 0 | AU24: 19.5
A25: 550250114013122 | B25: 7008 | C25: 2 | D25: 0.095129376 | E25: 2 | G25: 0 | AF25: 37 | AG25: 1 | AH25: 30 | AL25: 1 | AN25: 0 | AR25: 6.9450299 | AS25: 0 | AU25: 19.5
A26: 550250112004007 | B26: 2228 | C26: 45 | D26: 6.7324955 | T26: 1 | V26: 0 | AF26: 5 | AH26: 0 | AR26: 2.0197487 | AT26: 0 | AU26: 0
A27: 550250109031044
A28: 550250015022019 | B28: 7144 | C28: 557 | D28: 18.464857 | Z28: 2 | AB28: 0 | AF28: 24 | AG28: 6 | AH28: 74.285714 | AL28: 5 | AN28: 0 | AR28: 21.403978 | AT28: 0 | AU28: 48.285714
A29: 550250112004020 | B29: 1632 | C29: 20 | D29: 4.0849673 | T29: 1 | V29: 0 | AF29: 10 | AH29: 0 | AR29: 1.2254902 | AT29: 0 | AU29: 0
A30: 550250114013114 | B30: 7790 | C30: 48 | D30: 2.0539153 | E30: 2 | G30: 0 | AF30: 39 | AH30: 0 | AL30: 1 | AN30: 0 | AR30: 0.47398045 | AS30: 0 | AU30: 0
A31: 550250114013115 | B31: 3545 | D31: 0 | E31: 1 | G31: 0 | AF31: 27 | AH31: 0 | AL31: 1 | AN31: 0 | AR31: 0 | AS31: 0 | AU31: 0
A32: 550250114013117 | B32: 3829 | C32: 62 | D32: 5.3974058 | E32: 1 | G32: 0 | AF32: 29 | AH32: 0 | AL32: 1 | AN32: 0 | AR32: 1.2455552 | AS32: 0 | AU32: 0
A33: 550250114013118 | B33: 2669 | C33: 0 | D33: 0 | E33: 1 | G33: 0 | AF33: 18 | AH33: 0 | AL33: 1 | AN33: 0 | AR33: 0 | AS33: 0 | AU33: 0
A34: 550250105011016 | B34: 6991 | C34: 2 | D34: 0.095360702 | E34: 2 | G34: 0 | AF34: 37 | AG34: 1 | AH34: 30 | AL34: 2 | AN34: 0 | AR34: 6.9450832 | AS34: 0 | AU34: 19.5
A35: 550250114013119 | B35: 3902 | C35: 18 | D35: 1.537673 | E35: 1 | G35: 0 | AF35: 28 | AH35: 0 | AL35: 1 | AN35: 0 | AR35: 0.35484761 | AS35: 0 | AU35: 0
A36: 550250015023030 | B36: 10455 | C36: 709 | D36: 16.673137 | E36: 1 | G36: 0 | Z36: 1 | AB36: 0 | AF36: 29 | AG36: 5 | AH36: 72.307692 | AL36: 2 | AN36: 0 | AR36: 15.702499 | AS36: 0 | AT36: 0 | AU36: 47
A37: 550250114013088 | B37: 4770 | C37: 2 | D37: 0.1397624 | E37: 1 | G37: 0 | AF37: 34 | AH37: 0 | AL37: 1 | AM37: 1 | AN37: 100 | AR37: 23.109176 | AS37: 0 | AU37: 0
A38: 550250109011161 | B38: 9831 | C38: 872 | D38: 20.358649 | E38: 2 | F38: 1 | G38: 30 | Q38: 1 | S38: 0 | AF38: 35 | AG38: 9 | AH38: 75.625 | AR38: 29.139353 | AS38: 19.5 | AT38: 0 | AU38: 49.15625
A39: 550250005012001 | B39: 36478 | C39: 272 | D39: 2.4855164 | E39: 8 | G39: 0 | N39: 2 | P39: 0 | Q39: 5 | S39: 0 | W39: 3 | Y39: 0 | Z39: 5 | AB39: 0 | AC39: 3 | AE39: 0 | AF39: 60 | AH39: 0 | AI39: 3 | AK39: 0 | AL39: 8 | AN39: 0 | AO39: 1 | AQ39: 0 | AR39: 0.37282746 | AS39: 0 | AT39: 0 | AU39: 0
A40: 550250006001029 | B40: 33895 | C40: 12308 | D40: 61.749521 | E40: 8 | F40: 2 | G40: 50 | N40: 3 | P40: 0 | Q40: 3 | R40: 1 | S40: 40 | W40: 3 | Y40: 0 | Z40: 3 | AA40: 1 | AB40: 60 | AC40: 3 | AD40: 2 | AE40: 85 | AF40: 51 | AG40: 25 | AH40: 83.75 | AI40: 3 | AJ40: 2 | AK40: 60 | AL40: 6 | AM40: 2 | AN40: 60 | AR40: 55.755572 | AS40: 32.5 | AT40: 39.6875 | AU40: 48.5
...

Sheet pybna_raw
A1: blockid10 | B1: people_hs | C1: people_ls | D1: people_score | E1: schools_hs | F1: schools_ls | G1: schools_score | H1: colleges_hs | I1: colleges_ls | J1: colleges_score | K1: universities_hs | L1: universities_ls | M1: universities_score | N1: doctors_hs | O1: doctors_ls | P1: doctors_score | Q1: dentists_hs | R1: dentists_ls | S1: dentists_score | T1: hospitals_hs | U1: hospitals_ls | V1: hospitals_score | W1: pharmacies_hs | X1: pharmacies_ls | Y1: pharmacies_score | Z1: supermarkets_hs | AA1: supermarkets_ls | AB1: supermarkets_score | AC1: social_services_hs | AD1: social_services_ls | AE1: social_services_score | AF1: parks_hs | AG1: parks_ls | AH1: parks_score | AI1: community_centers_hs | AJ1: community_centers_ls | AK1: community_centers_score | AL1: retail_hs | AM1: retail_ls | AN1: retail_score | AO1: transit_hs | AP1: transit_ls | AQ1: transit_score | AR1: overall_score | AS1: opportunity_score | AT1: core_services_score | AU1: recreation_score
A2: 550250023021019
A3: 550250001001002 | B3: 17956 | C3: 3728 | D3: 41.015816 | E3: 9 | F3: 2 | G3: 50 | N3: 1 | O3: 1 | P3: 100 | Q3: 3 | R3: 2 | S3: 60 | W3: 2 | X3: 1 | Y3: 40 | Z3: 2 | AB3: 0 | AF3: 26 | AG3: 9 | AH3: 77.826087 | AL3: 1 | AM3: 1 | AN3: 100 | AR3: 61.243594 | AS3: 32.5 | AT3: 46.153846 | AU3: 50.586957
A4: 550250010001035
A5: 550250026032000 | B5: 3394 | C5: 0 | D5: 0 | E5: 1 | G5: 0 | AF5: 3 | AH5: 0 | AL5: 4 | AN5: 0 | AR5: 0 | AS5: 0 | AU5: 0
A6: 550250009024026
A7: 550250105021000 | B7: 7715 | C7: 39 | D7: 1.6850292 | E7: 1 | G7: 0 | AF7: 13 | AH7: 0 | AR7: 0.50550875 | AS7: 0 | AU7: 0
A8: 550250023021017
A9: 550250010001038
A10: 550250105011018 | B10: 9288 | C10: 737 | D10: 18.70877 | E10: 3 | G10: 0 | Z10: 1 | AB10: 0 | AF10: 18 | AG10: 1 | AH10: 30 | AR10: 10.437594 | AS10: 0 | AT10: 0 | AU10: 19.5
A11: 550250112003007
A12: 550250114021057 | B12: 2305 | C12: 562 | D12: 45.842372 | E12: 1 | G12: 0 | AF12: 1 | AH12: 0 | AL12: 1 | AN12: 0 | AR12: 10.579009 | AS12: 0 | AU12: 0
A13: 550250109031058 | B13: 3902 | C13: 0 | D13: 0 | E13: 1 | G13: 0 | AC13: 1 | AE13: 0 | AF13: 6 | AH13: 0 | AR13: 0 | AS13: 0 | AT13: 0 | AU13: 0
A14: 550250109011053 | B14: 7200 | C14: 951 | D14: 28.014706 | Q14: 1 | S14: 0 | AF14: 6 | AG14: 2 | AH14: 50 | AR14: 23.404412 | AT14: 0 | AU14: 32.5
A15: 550250117002054 | B15: 1685 | C15: 782 | D15: 75.212661 | E15: 1 | G15: 0 | AR15: 32.233997 | AS15: 0
A16: 550250023021016 | B16: 8212 | C16: 713 | D16: 20.027793 | E16: 2 | G16: 0 | AC16: 1 | AE16: 0 | AF16: 5 | AG16: 1 | AH16: 30 | AR16: 10.720241 | AS16: 0 | AT16: 0 | AU16: 19.5
A17: 550250114021047 | B17: 4628 | C17: 19 | D17: 1.3684817 | E17: 1 | G17: 0 | AF17: 4 | AH17: 0 | AL17: 2 | AN17: 0 | AR17: 0.31580347 | AS17: 0 | AU17: 0
A18: 550250114022015 | B18: 1217 | C18: 0 | D18: 0 | AF18: 1 | AH18: 0 | AL18: 1 | AN18: 0 | AR18: 0 | AU18: 0
A19: 550250109031049 | B19: 3546 | C19: 0 | D19: 0 | E19: 1 | G19: 0 | AF19: 4 | AH19: 0 | AR19: 0 | AS19: 0 | AU19: 0
A20: 550250002042015
A21: 550250023021036
A22: 550250114013093 | B22: 149 | C22: 0 | D22: 0 | AR22: 0
A23: 550250026032010
A24: 550250114013083
A25: 550250026032050
A26: 550250109011043 | B26: 5269 | C26: 3365 | D26: 85.545644 | N26: 1 | O26: 1 | P26: 100 | W26: 1 | Y26: 0 | AF26: 4 | AG26: 3 | AH26: 70 | AR26: 73.33036 | AT26: 66.666667 | AU26: 45.5
A27: 550250010001010
A28: 550250114011054 | B28: 10423 | C28: 0 | D28: 0 | E28: 1 | G28: 0 | Q28: 3 | S28: 0 | Z28: 1 | AB28: 0 | AF28: 7 | AH28: 0 | AR28: 0 | AS28: 0 | AT28: 0 | AU28: 0
A29: 550250114022026
A30: 550250114023091 | B30: 1823 | C30: 343 | D30: 37.90907 | AF30: 2 | AH30: 0 | AR30: 18.954535 | AU30: 0
A31: 550250114013117 | B31: 724 | C31: 48 | D31: 16.40559 | E31: 1 | G31: 0 | AR31: 7.0309671 | AS31: 0
A32: 550250026032048
A33: 550250026032001 | B33: 2072 | C33: 0 | D33: 0 | AF33: 1 | AH33: 0 | AL33: 2 | AN33: 0 | AR33: 0 | AU33: 0
A34: 550250010001008
A35: 550250114012001 | B35: 780 | C35: 0 | D35: 0 | AF35: 2 | AH35: 0 | AR35: 0 | AU35: 0
A36: 550250005043026 | B36: 17772 | C36: 4837 | D36: 49.622627 | E36: 2 | G36: 0 | W36: 1 | Y36: 0 | Z36: 1 | AB36: 0 | AC36: 2 | AD36: 1 | AE36: 70 | AF36: 20 | AG36: 5 | AH36: 73.529412 | AL36: 1 | AN36: 0 | AR36: 26.673889 | AS36: 0 | AT36: 21 | AU36: 47.794118
A37: 550250032001018 | B37: 978 | C37: 978 | D37: 100 | AF37: 3 | AG37: 3 | AH37: 100 | AR37: 100 | AU37: 65
A38: 550250002042017
A39: 550250109031010 | B39: 4345 | C39: 1463 | D39: 58.227848 | E39: 1 | G39: 0 | AF39: 8 | AG39: 1 | AH39: 30 | AR39: 26.468354 | AS39: 0 | AU39: 19.5
A40: 550250112004016 | B40: 1057 | C40: 33 | D40: 10.215371 | AF40: 1 | AH40: 0 | AR40: 5.1076855 | AU40: 0
...
